2021-02-06 17:23:43,626 	 [INFO | driver.py:22] > Driver setting up ...
2021-02-06 17:23:43,643 	 [INFO | driver.py:47] > [.] Running job LeagueMembershipCacheJob at 2021-02-06 17:23:43.643084
2021-02-06 17:25:08,378 	 [INFO | driver.py:22] > Driver setting up ...
2021-02-06 17:25:08,394 	 [INFO | driver.py:47] > [.] Running job LeagueMembershipCacheJob at 2021-02-06 17:25:08.394834
2021-02-06 17:25:15,692 	 [INFO | officialFPLApi.py:156] > Collecting classic league standings for 854530
2021-02-06 17:25:15,692 	 [INFO | officialFPLApi.py:161] > Request for classic league standings : https://fantasy.premierleague.com/api/leagues-classic/854530/standings/
2021-02-06 17:25:16,427 	 [INFO | officialFPLApi.py:165] > Collected response for classic league standings : {'league': {'id': 854530, 'name': 'Justice league :D', 'created': '2020-09-09T15:45:20.296151Z', 'closed': False, 'max_entries': None, 'league_type': 'x', 'scoring': 'c', 'admin_entry': 3753381, 'start_event': 1, 'code_privacy': 'p', 'has_cup': False, 'cup_league': None, 'rank': None}, 'new_entries': {'has_next': False, 'page': 1, 'results': []}, 'standings': {'has_next': False, 'page': 1, 'results': [{'id': 22698054, 'event_total': 0, 'player_name': 'Rohit Roy', 'rank': 1, 'last_rank': 1, 'rank_sort': 1, 'total': 1383, 'entry': 2599752, 'entry_name': "Shambu's kids"}, {'id': 22698056, 'event_total': 0, 'player_name': 'Nitin Krishna', 'rank': 2, 'last_rank': 2, 'rank_sort': 2, 'total': 1347, 'entry': 799765, 'entry_name': 'NiñeXI'}, {'id': 31547344, 'event_total': 0, 'player_name': 'Sherine Davis', 'rank': 3, 'last_rank': 3, 'rank_sort': 3, 'total': 1335, 'entry': 4979783, 'entry_name': 'Da Sher'}, {'id': 22698061, 'event_total': 0, 'player_name': 'Vijay Ganapathy Girish', 'rank': 4, 'last_rank': 4, 'rank_sort': 4, 'total': 1320, 'entry': 427885, 'entry_name': "Vijayettan's XI"}, {'id': 22698059, 'event_total': 0, 'player_name': 'Sanjo Jain', 'rank': 5, 'last_rank': 5, 'rank_sort': 5, 'total': 1319, 'entry': 489665, 'entry_name': 'KappaFishcurryXI'}, {'id': 22698050, 'event_total': 0, 'player_name': 'Janardhan Kammath', 'rank': 6, 'last_rank': 6, 'rank_sort': 6, 'total': 1318, 'entry': 3753381, 'entry_name': 'Kallummakkais'}, {'id': 29649115, 'event_total': 0, 'player_name': 'Aryabhatt M R', 'rank': 7, 'last_rank': 7, 'rank_sort': 7, 'total': 1306, 'entry': 4710397, 'entry_name': 'ole ole ole'}, {'id': 22698058, 'event_total': 0, 'player_name': 'Ajish Philip', 'rank': 8, 'last_rank': 8, 'rank_sort': 8, 'total': 1279, 'entry': 2925830, 'entry_name': 'MFC'}, {'id': 35959276, 'event_total': 0, 'player_name': 'Sreeraj Janardhanan', 'rank': 9, 'last_rank': 9, 'rank_sort': 9, 'total': 1267, 'entry': 5572779, 'entry_name': 'Purge'}, {'id': 22839657, 'event_total': 0, 'player_name': 'Ramakrishnan Natarajan', 'rank': 10, 'last_rank': 10, 'rank_sort': 10, 'total': 1247, 'entry': 3165748, 'entry_name': 'Gilphonsi Malpova'}, {'id': 23262481, 'event_total': 0, 'player_name': 'Vishnu Prabhakar', 'rank': 11, 'last_rank': 11, 'rank_sort': 11, 'total': 1233, 'entry': 3831449, 'entry_name': 'Lord8ar2omeuFC'}, {'id': 22732254, 'event_total': 0, 'player_name': 'Jeremy Elengical', 'rank': 12, 'last_rank': 12, 'rank_sort': 12, 'total': 1197, 'entry': 3758444, 'entry_name': 'Crystal Phallus'}, {'id': 22698053, 'event_total': 0, 'player_name': 'Shivaraj Jayakumar', 'rank': 13, 'last_rank': 13, 'rank_sort': 13, 'total': 1159, 'entry': 468623, 'entry_name': 'Überdogs'}, {'id': 22698052, 'event_total': 0, 'player_name': 'satrujit mohanty', 'rank': 14, 'last_rank': 14, 'rank_sort': 14, 'total': 1136, 'entry': 1664036, 'entry_name': 'OnlyTillNovember FC'}, {'id': 29512318, 'event_total': 0, 'player_name': 'Vishnu Balakrishnan', 'rank': 15, 'last_rank': 15, 'rank_sort': 15, 'total': 995, 'entry': 4693999, 'entry_name': 'Gilphonsi Malpova'}, {'id': 35492143, 'event_total': 0, 'player_name': 'Anwin P S', 'rank': 16, 'last_rank': 16, 'rank_sort': 16, 'total': 993, 'entry': 5510973, 'entry_name': 'an_archist'}, {'id': 31905386, 'event_total': 0, 'player_name': 'Shahabas Shamsad', 'rank': 17, 'last_rank': 17, 'rank_sort': 17, 'total': 992, 'entry': 5032016, 'entry_name': 'Kondotty Bros.'}, {'id': 27698739, 'event_total': 0, 'player_name': 'Sam Radhakrishnan', 'rank': 18, 'last_rank': 18, 'rank_sort': 18, 'total': 942, 'entry': 4452170, 'entry_name': 'Childish Firmino'}, {'id': 30293794, 'event_total': 0, 'player_name': 'Aravind Krishnan', 'rank': 19, 'last_rank': 19, 'rank_sort': 19, 'total': 912, 'entry': 4804247, 'entry_name': 'Warrrr'}, {'id': 28967597, 'event_total': 0, 'player_name': 'Sai Chaithanya', 'rank': 20, 'last_rank': 20, 'rank_sort': 20, 'total': 862, 'entry': 4622834, 'entry_name': 'The Imparables'}]}}
2021-02-06 17:25:44,496 	 [INFO | leagueMembershipCacheJob.py:24] > A
2021-02-06 17:26:05,465 	 [INFO | driver.py:49] > [.] Completed job LeagueMembershipCacheJob at 2021-02-06 17:26:05.465612
2021-02-06 17:28:23,679 	 [INFO | driver.py:22] > Driver setting up ...
2021-02-06 17:28:23,679 	 [INFO | driver.py:47] > [.] Running job FPLBootstrapDataUpdateJob at 2021-02-06 17:28:23.679226
2021-02-06 17:28:32,784 	 [INFO | officialFPLApi.py:113] > Collecting bootstrap static data
2021-02-06 17:28:32,784 	 [INFO | officialFPLApi.py:118] > Request for bootstrap static data : https://fantasy.premierleague.com/api/bootstrap-static/
2021-02-06 17:41:37,187 	 [INFO | driver.py:22] > Driver setting up ...
2021-02-06 17:41:37,195 	 [INFO | driver.py:47] > [.] Running job FPLBootstrapDataUpdateJob at 2021-02-06 17:41:37.195597
2021-02-06 17:41:44,359 	 [INFO | officialFPLApi.py:113] > Collecting bootstrap static data
2021-02-06 17:41:44,359 	 [INFO | officialFPLApi.py:118] > Request for bootstrap static data : https://fantasy.premierleague.com/api/bootstrap-static/
2021-02-06 17:41:48,768 	 [INFO | driver.py:49] > [.] Completed job FPLBootstrapDataUpdateJob at 2021-02-06 17:41:48.768855
2021-02-06 17:49:08,485 	 [INFO | driver.py:22] > Driver setting up ...
2021-02-06 17:49:08,485 	 [INFO | driver.py:47] > [.] Running job FPLBootstrapDataUpdateJob at 2021-02-06 17:49:08.485871
2021-02-06 17:49:08,485 	 [ERROR | baseJob.py:16] >  + Starting job : FPLBootstrapDataUpdateJob
NoneType: None
2021-02-06 17:49:08,485 	 [ERROR | baseJob.py:23] >  ! Failure while running job : FPLBootstrapDataUpdateJob
Traceback (most recent call last):
  File "D:\Sherine Davis\Code\PycharmProjects\FPLDasherboard\fpldb\driver\job\baseJob.py", line 20, in start
    self.recordActivity(ActivityStatus.Started)
TypeError: recordActivity() missing 1 required positional argument: 'gw'
2021-02-06 17:50:30,813 	 [INFO | driver.py:22] > Driver setting up ...
2021-02-06 17:50:30,821 	 [INFO | driver.py:47] > [.] Running job FPLBootstrapDataUpdateJob at 2021-02-06 17:50:30.821231
2021-02-06 17:50:30,821 	 [ERROR | baseJob.py:16] >  + Starting job : FPLBootstrapDataUpdateJob
NoneType: None
2021-02-06 17:50:30,821 	 [ERROR | baseJob.py:23] >  ! Failure while running job : FPLBootstrapDataUpdateJob
Traceback (most recent call last):
  File "D:\Sherine Davis\Code\PycharmProjects\FPLDasherboard\fpldb\driver\job\baseJob.py", line 20, in start
    self.recordActivity(ActivityStatus.Started)
  File "D:\Sherine Davis\Code\PycharmProjects\FPLDasherboard\fpldb\driver\job\baseJob.py", line 31, in recordActivity
    if 'key' not in self or self.key is None:
TypeError: argument of type 'FPLBootstrapDataUpdateJob' is not iterable
2021-02-06 17:51:56,269 	 [INFO | driver.py:22] > Driver setting up ...
2021-02-06 17:51:56,269 	 [INFO | driver.py:47] > [.] Running job FPLBootstrapDataUpdateJob at 2021-02-06 17:51:56.269227
2021-02-06 17:51:56,269 	 [ERROR | baseJob.py:16] >  + Starting job : FPLBootstrapDataUpdateJob
NoneType: None
2021-02-06 17:52:06,046 	 [INFO | officialFPLApi.py:113] > Collecting bootstrap static data
2021-02-06 17:52:06,046 	 [INFO | officialFPLApi.py:118] > Request for bootstrap static data : https://fantasy.premierleague.com/api/bootstrap-static/
2021-02-06 17:52:10,143 	 [ERROR | baseJob.py:27] >  + Completed running job : FPLBootstrapDataUpdateJob
NoneType: None
2021-02-06 17:52:11,784 	 [INFO | driver.py:49] > [.] Completed job FPLBootstrapDataUpdateJob at 2021-02-06 17:52:11.784228
2021-02-06 17:54:05,396 	 [INFO | driver.py:22] > Driver setting up ...
2021-02-06 17:54:05,405 	 [INFO | driver.py:47] > [.] Running job FPLBootstrapDataUpdateJob at 2021-02-06 17:54:05.405172
2021-02-06 17:54:05,405 	 [ERROR | baseJob.py:16] >  + Starting job : FPLBootstrapDataUpdateJob
NoneType: None
2021-02-06 17:54:16,010 	 [INFO | officialFPLApi.py:113] > Collecting bootstrap static data
2021-02-06 17:54:16,010 	 [INFO | officialFPLApi.py:118] > Request for bootstrap static data : https://fantasy.premierleague.com/api/bootstrap-static/
2021-02-06 17:54:20,393 	 [ERROR | baseJob.py:27] >  + Completed running job : FPLBootstrapDataUpdateJob
NoneType: None
2021-02-06 17:54:22,034 	 [INFO | driver.py:49] > [.] Completed job FPLBootstrapDataUpdateJob at 2021-02-06 17:54:22.034912
2021-02-06 17:55:10,323 	 [INFO | driver.py:22] > Driver setting up ...
2021-02-06 17:55:10,331 	 [INFO | driver.py:47] > [.] Running job FPLBootstrapDataUpdateJob at 2021-02-06 17:55:10.331297
2021-02-06 17:55:10,339 	 [ERROR | baseJob.py:16] >  + Starting job : FPLBootstrapDataUpdateJob
NoneType: None
2021-02-06 17:56:04,318 	 [ERROR | baseJob.py:23] >  ! Failure while running job : FPLBootstrapDataUpdateJob
Traceback (most recent call last):
  File "C:\Users\sheri\AppData\Local\Programs\Python\Python39\lib\site-packages\sqlalchemy\engine\base.py", line 1276, in _execute_context
    self.dialect.do_execute(
  File "C:\Users\sheri\AppData\Local\Programs\Python\Python39\lib\site-packages\sqlalchemy\engine\default.py", line 609, in do_execute
    cursor.execute(statement, parameters)
  File "C:\Users\sheri\AppData\Local\Programs\Python\Python39\lib\site-packages\MySQLdb\cursors.py", line 206, in execute
    res = self._query(query)
  File "C:\Users\sheri\AppData\Local\Programs\Python\Python39\lib\site-packages\MySQLdb\cursors.py", line 319, in _query
    db.query(q)
  File "C:\Users\sheri\AppData\Local\Programs\Python\Python39\lib\site-packages\MySQLdb\connections.py", line 259, in query
    _mysql.connection.query(self, query)
MySQLdb._exceptions.OperationalError: (2013, 'Lost connection to MySQL server during query')

The above exception was the direct cause of the following exception:

Traceback (most recent call last):
  File "D:\Sherine Davis\Code\PycharmProjects\FPLDasherboard\fpldb\driver\job\baseJob.py", line 20, in start
    self.recordActivity(ActivityStatus.Started)
  File "D:\Sherine Davis\Code\PycharmProjects\FPLDasherboard\fpldb\driver\job\baseJob.py", line 40, in recordActivity
    self.session.commit()
  File "C:\Users\sheri\AppData\Local\Programs\Python\Python39\lib\site-packages\sqlalchemy\orm\session.py", line 1046, in commit
    self.transaction.commit()
  File "C:\Users\sheri\AppData\Local\Programs\Python\Python39\lib\site-packages\sqlalchemy\orm\session.py", line 504, in commit
    self._prepare_impl()
  File "C:\Users\sheri\AppData\Local\Programs\Python\Python39\lib\site-packages\sqlalchemy\orm\session.py", line 483, in _prepare_impl
    self.session.flush()
  File "C:\Users\sheri\AppData\Local\Programs\Python\Python39\lib\site-packages\sqlalchemy\orm\session.py", line 2540, in flush
    self._flush(objects)
  File "C:\Users\sheri\AppData\Local\Programs\Python\Python39\lib\site-packages\sqlalchemy\orm\session.py", line 2682, in _flush
    transaction.rollback(_capture_exception=True)
  File "C:\Users\sheri\AppData\Local\Programs\Python\Python39\lib\site-packages\sqlalchemy\util\langhelpers.py", line 68, in __exit__
    compat.raise_(
  File "C:\Users\sheri\AppData\Local\Programs\Python\Python39\lib\site-packages\sqlalchemy\util\compat.py", line 182, in raise_
    raise exception
  File "C:\Users\sheri\AppData\Local\Programs\Python\Python39\lib\site-packages\sqlalchemy\orm\session.py", line 2642, in _flush
    flush_context.execute()
  File "C:\Users\sheri\AppData\Local\Programs\Python\Python39\lib\site-packages\sqlalchemy\orm\unitofwork.py", line 422, in execute
    rec.execute(self)
  File "C:\Users\sheri\AppData\Local\Programs\Python\Python39\lib\site-packages\sqlalchemy\orm\unitofwork.py", line 586, in execute
    persistence.save_obj(
  File "C:\Users\sheri\AppData\Local\Programs\Python\Python39\lib\site-packages\sqlalchemy\orm\persistence.py", line 205, in save_obj
    for (
  File "C:\Users\sheri\AppData\Local\Programs\Python\Python39\lib\site-packages\sqlalchemy\orm\persistence.py", line 373, in _organize_states_for_save
    for state, dict_, mapper, connection in _connections_for_states(
  File "C:\Users\sheri\AppData\Local\Programs\Python\Python39\lib\site-packages\sqlalchemy\orm\persistence.py", line 1602, in _connections_for_states
    connection = uowtransaction.transaction.connection(base_mapper)
  File "C:\Users\sheri\AppData\Local\Programs\Python\Python39\lib\site-packages\sqlalchemy\orm\session.py", line 314, in connection
    return self._connection_for_bind(bind, execution_options)
  File "C:\Users\sheri\AppData\Local\Programs\Python\Python39\lib\site-packages\sqlalchemy\orm\session.py", line 421, in _connection_for_bind
    conn = self._parent._connection_for_bind(bind, execution_options)
  File "C:\Users\sheri\AppData\Local\Programs\Python\Python39\lib\site-packages\sqlalchemy\orm\session.py", line 433, in _connection_for_bind
    conn = bind._contextual_connect()
  File "C:\Users\sheri\AppData\Local\Programs\Python\Python39\lib\site-packages\sqlalchemy\engine\base.py", line 2302, in _contextual_connect
    self._wrap_pool_connect(self.pool.connect, None),
  File "C:\Users\sheri\AppData\Local\Programs\Python\Python39\lib\site-packages\sqlalchemy\engine\base.py", line 2336, in _wrap_pool_connect
    return fn()
  File "C:\Users\sheri\AppData\Local\Programs\Python\Python39\lib\site-packages\sqlalchemy\pool\base.py", line 364, in connect
    return _ConnectionFairy._checkout(self)
  File "C:\Users\sheri\AppData\Local\Programs\Python\Python39\lib\site-packages\sqlalchemy\pool\base.py", line 778, in _checkout
    fairy = _ConnectionRecord.checkout(pool)
  File "C:\Users\sheri\AppData\Local\Programs\Python\Python39\lib\site-packages\sqlalchemy\pool\base.py", line 495, in checkout
    rec = pool._do_get()
  File "C:\Users\sheri\AppData\Local\Programs\Python\Python39\lib\site-packages\sqlalchemy\pool\impl.py", line 140, in _do_get
    self._dec_overflow()
  File "C:\Users\sheri\AppData\Local\Programs\Python\Python39\lib\site-packages\sqlalchemy\util\langhelpers.py", line 68, in __exit__
    compat.raise_(
  File "C:\Users\sheri\AppData\Local\Programs\Python\Python39\lib\site-packages\sqlalchemy\util\compat.py", line 182, in raise_
    raise exception
  File "C:\Users\sheri\AppData\Local\Programs\Python\Python39\lib\site-packages\sqlalchemy\pool\impl.py", line 137, in _do_get
    return self._create_connection()
  File "C:\Users\sheri\AppData\Local\Programs\Python\Python39\lib\site-packages\sqlalchemy\pool\base.py", line 309, in _create_connection
    return _ConnectionRecord(self)
  File "C:\Users\sheri\AppData\Local\Programs\Python\Python39\lib\site-packages\sqlalchemy\pool\base.py", line 440, in __init__
    self.__connect(first_connect_check=True)
  File "C:\Users\sheri\AppData\Local\Programs\Python\Python39\lib\site-packages\sqlalchemy\pool\base.py", line 664, in __connect
    pool.dispatch.first_connect.for_modify(
  File "C:\Users\sheri\AppData\Local\Programs\Python\Python39\lib\site-packages\sqlalchemy\event\attr.py", line 314, in exec_once_unless_exception
    self._exec_once_impl(True, *args, **kw)
  File "C:\Users\sheri\AppData\Local\Programs\Python\Python39\lib\site-packages\sqlalchemy\event\attr.py", line 285, in _exec_once_impl
    self(*args, **kw)
  File "C:\Users\sheri\AppData\Local\Programs\Python\Python39\lib\site-packages\sqlalchemy\event\attr.py", line 322, in __call__
    fn(*args, **kw)
  File "C:\Users\sheri\AppData\Local\Programs\Python\Python39\lib\site-packages\sqlalchemy\util\langhelpers.py", line 1406, in go
    return once_fn(*arg, **kw)
  File "C:\Users\sheri\AppData\Local\Programs\Python\Python39\lib\site-packages\sqlalchemy\engine\strategies.py", line 199, in first_connect
    dialect.initialize(c)
  File "C:\Users\sheri\AppData\Local\Programs\Python\Python39\lib\site-packages\sqlalchemy\dialects\mysql\base.py", line 2634, in initialize
    default.DefaultDialect.initialize(self, connection)
  File "C:\Users\sheri\AppData\Local\Programs\Python\Python39\lib\site-packages\sqlalchemy\engine\default.py", line 331, in initialize
    self.returns_unicode_strings = self._check_unicode_returns(connection)
  File "C:\Users\sheri\AppData\Local\Programs\Python\Python39\lib\site-packages\sqlalchemy\dialects\mysql\mysqldb.py", line 159, in _check_unicode_returns
    ) and connection.scalar(
  File "C:\Users\sheri\AppData\Local\Programs\Python\Python39\lib\site-packages\sqlalchemy\engine\base.py", line 941, in scalar
    return self.execute(object_, *multiparams, **params).scalar()
  File "C:\Users\sheri\AppData\Local\Programs\Python\Python39\lib\site-packages\sqlalchemy\engine\base.py", line 1003, in execute
    return self._execute_text(object_, multiparams, params)
  File "C:\Users\sheri\AppData\Local\Programs\Python\Python39\lib\site-packages\sqlalchemy\engine\base.py", line 1172, in _execute_text
    ret = self._execute_context(
  File "C:\Users\sheri\AppData\Local\Programs\Python\Python39\lib\site-packages\sqlalchemy\engine\base.py", line 1316, in _execute_context
    self._handle_dbapi_exception(
  File "C:\Users\sheri\AppData\Local\Programs\Python\Python39\lib\site-packages\sqlalchemy\engine\base.py", line 1510, in _handle_dbapi_exception
    util.raise_(
  File "C:\Users\sheri\AppData\Local\Programs\Python\Python39\lib\site-packages\sqlalchemy\util\compat.py", line 182, in raise_
    raise exception
  File "C:\Users\sheri\AppData\Local\Programs\Python\Python39\lib\site-packages\sqlalchemy\engine\base.py", line 1276, in _execute_context
    self.dialect.do_execute(
  File "C:\Users\sheri\AppData\Local\Programs\Python\Python39\lib\site-packages\sqlalchemy\engine\default.py", line 609, in do_execute
    cursor.execute(statement, parameters)
  File "C:\Users\sheri\AppData\Local\Programs\Python\Python39\lib\site-packages\MySQLdb\cursors.py", line 206, in execute
    res = self._query(query)
  File "C:\Users\sheri\AppData\Local\Programs\Python\Python39\lib\site-packages\MySQLdb\cursors.py", line 319, in _query
    db.query(q)
  File "C:\Users\sheri\AppData\Local\Programs\Python\Python39\lib\site-packages\MySQLdb\connections.py", line 259, in query
    _mysql.connection.query(self, query)
sqlalchemy.exc.OperationalError: (MySQLdb._exceptions.OperationalError) (2013, 'Lost connection to MySQL server during query')
[SQL: show collation where `Charset` = 'utf8mb4' and `Collation` = 'utf8mb4_bin']
(Background on this error at: http://sqlalche.me/e/13/e3q8)
2021-02-06 17:58:04,436 	 [INFO | driver.py:22] > Driver setting up ...
2021-02-06 17:58:04,445 	 [INFO | driver.py:47] > [.] Running job FPLBootstrapDataUpdateJob at 2021-02-06 17:58:04.445323
2021-02-06 17:58:24,014 	 [ERROR | baseJob.py:16] >  + Starting job : FPLBootstrapDataUpdateJob
NoneType: None
2021-02-06 17:59:17,689 	 [INFO | driver.py:22] > Driver setting up ...
2021-02-06 17:59:17,697 	 [INFO | driver.py:47] > [.] Running job FPLBootstrapDataUpdateJob at 2021-02-06 17:59:17.697533
2021-02-06 17:59:28,470 	 [INFO | officialFPLApi.py:91] > Collecting event status
2021-02-06 17:59:28,470 	 [INFO | officialFPLApi.py:96] > Request for event status : https://fantasy.premierleague.com/api/event-status/
2021-02-06 18:00:07,565 	 [ERROR | baseJob.py:23] >  ! Failure while running job : FPLBootstrapDataUpdateJob
Traceback (most recent call last):
  File "D:\Sherine Davis\Code\PycharmProjects\FPLDasherboard\fpldb\driver\job\baseJob.py", line 16, in start
    if self.criteria and not self.criteria.isValid():
  File "D:\Sherine Davis\Code\PycharmProjects\FPLDasherboard\fpldb\driver\criterion\criterion.py", line 44, in isValid
    if self.alreadyCompleted():
  File "D:\Sherine Davis\Code\PycharmProjects\FPLDasherboard\fpldb\driver\criterion\criterion.py", line 29, in alreadyCompleted
    log = self.session(ActivityLog).filter(ActivityLog.activityId == self.key, ActivityLog.status.in_([ActivityStatus.Completed, ActivityStatus.Started, ActivityStatus.Processing])).order_by(ActivityLog.completionTime.desc()).first()
TypeError: 'Session' object is not callable
2021-02-06 18:00:51,343 	 [INFO | driver.py:22] > Driver setting up ...
2021-02-06 18:00:51,343 	 [INFO | driver.py:47] > [.] Running job FPLBootstrapDataUpdateJob at 2021-02-06 18:00:51.343983
2021-02-06 18:00:51,343 	 [INFO | officialFPLApi.py:91] > Collecting event status
2021-02-06 18:00:51,343 	 [INFO | officialFPLApi.py:96] > Request for event status : https://fantasy.premierleague.com/api/event-status/
2021-02-06 18:01:01,122 	 [INFO | driver.py:22] > Driver setting up ...
2021-02-06 18:01:01,130 	 [INFO | driver.py:47] > [.] Running job FPLBootstrapDataUpdateJob at 2021-02-06 18:01:01.130969
2021-02-06 18:07:27,540 	 [INFO | officialFPLApi.py:91] > Collecting event status
2021-02-06 18:07:27,540 	 [INFO | officialFPLApi.py:96] > Request for event status : https://fantasy.premierleague.com/api/event-status/
2021-02-06 18:10:30,431 	 [INFO | baseJob.py:17] >  ! Job criteria not met for FPLBootstrapDataUpdateJob. Skipping execution
2021-02-06 18:10:44,322 	 [INFO | driver.py:49] > [.] Completed job FPLBootstrapDataUpdateJob at 2021-02-06 18:10:44.322832
